Workbook

Sheet sheet1
A2: 検索
A3: 書籍名など | C3: 棚 | D3: 段 | E3: 書籍名 | F3: 著者名 | G3: 出版社 | H3: 年 | I3: 備考
C4: {=IFERROR(IF($A$4="", "", INDEX(sheet2!$A:$H, MATCH(ROW(A1), sheet2!$H:$H, 0), COLUMN(A1))), "")} | D4: {=IFERROR(IF($A$4="", "", INDEX(sheet2!$A:$G, MATCH(ROW(B1), sheet2!$H:$H, 0), COLUMN(B1))), "")} | E4: {=IFERROR(IF($A$4="", "", INDEX(sheet2!$A:$G, MATCH(ROW(C1), sheet2!$H:$H, 0), COLUMN(C1))), "")} | F4: {=IFERROR(IF($A$4="", "", INDEX(sheet2!$A:$G, MATCH(ROW(D1), sheet2!$H:$H, 0), COLUMN(D1))), "")} | G4: {=IFERROR(IF($A$4="", "", INDEX(sheet2!$A:$G, MATCH(ROW(E1), sheet2!$H:$H, 0), COLUMN(E1))), "")} | H4: {=IFERROR(IF($A$4="", "", INDEX(sheet2!$A:$G, MATCH(ROW(F1), sheet2!$H:$H, 0), COLUMN(F1))), "")} | I4: {=IFERROR(IF($A$4="", "", INDEX(sheet2!$A:$G, MATCH(ROW(G1), sheet2!$H:$H, 0), COLUMN(G1))), "")}
C5: {=IFERROR(IF($A$4="", "", INDEX(sheet2!$A:$H, MATCH(ROW(A2), sheet2!$H:$H, 0), COLUMN(A2))), "")} | D5: {=IFERROR(IF($A$4="", "", INDEX(sheet2!$A:$G, MATCH(ROW(B2), sheet2!$H:$H, 0), COLUMN(B2))), "")} | E5: {=IFERROR(IF($A$4="", "", INDEX(sheet2!$A:$G, MATCH(ROW(C2), sheet2!$H:$H, 0), COLUMN(C2))), "")} | F5: {=IFERROR(IF($A$4="", "", INDEX(sheet2!$A:$G, MATCH(ROW(D2), sheet2!$H:$H, 0), COLUMN(D2))), "")} | G5: {=IFERROR(IF($A$4="", "", INDEX(sheet2!$A:$G, MATCH(ROW(E2), sheet2!$H:$H, 0), COLUMN(E2))), "")} | H5: {=IFERROR(IF($A$4="", "", INDEX(sheet2!$A:$G, MATCH(ROW(F2), sheet2!$H:$H, 0), COLUMN(F2))), "")} | I5: {=IFERROR(IF($A$4="", "", INDEX(sheet2!$A:$G, MATCH(ROW(G2), sheet2!$H:$H, 0), COLUMN(G2))), "")}
C6: {=IFERROR(IF($A$4="", "", INDEX(sheet2!$A:$H, MATCH(ROW(A3), sheet2!$H:$H, 0), COLUMN(A3))), "")} | D6: {=IFERROR(IF($A$4="", "", INDEX(sheet2!$A:$G, MATCH(ROW(B3), sheet2!$H:$H, 0), COLUMN(B3))), "")} | E6: {=IFERROR(IF($A$4="", "", INDEX(sheet2!$A:$G, MATCH(ROW(C3), sheet2!$H:$H, 0), COLUMN(C3))), "")} | F6: {=IFERROR(IF($A$4="", "", INDEX(sheet2!$A:$G, MATCH(ROW(D3), sheet2!$H:$H, 0), COLUMN(D3))), "")} | G6: {=IFERROR(IF($A$4="", "", INDEX(sheet2!$A:$G, MATCH(ROW(E3), sheet2!$H:$H, 0), COLUMN(E3))), "")} | H6: {=IFERROR(IF($A$4="", "", INDEX(sheet2!$A:$G, MATCH(ROW(F3), sheet2!$H:$H, 0), COLUMN(F3))), "")} | I6: {=IFERROR(IF($A$4="", "", INDEX(sheet2!$A:$G, MATCH(ROW(G3), sheet2!$H:$H, 0), COLUMN(G3))), "")}
C7: {=IFERROR(IF($A$4="", "", INDEX(sheet2!$A:$H, MATCH(ROW(A4), sheet2!$H:$H, 0), COLUMN(A4))), "")} | D7: {=IFERROR(IF($A$4="", "", INDEX(sheet2!$A:$G, MATCH(ROW(B4), sheet2!$H:$H, 0), COLUMN(B4))), "")} | E7: {=IFERROR(IF($A$4="", "", INDEX(sheet2!$A:$G, MATCH(ROW(C4), sheet2!$H:$H, 0), COLUMN(C4))), "")} | F7: {=IFERROR(IF($A$4="", "", INDEX(sheet2!$A:$G, MATCH(ROW(D4), sheet2!$H:$H, 0), COLUMN(D4))), "")} | G7: {=IFERROR(IF($A$4="", "", INDEX(sheet2!$A:$G, MATCH(ROW(E4), sheet2!$H:$H, 0), COLUMN(E4))), "")} | H7: {=IFERROR(IF($A$4="", "", INDEX(sheet2!$A:$G, MATCH(ROW(F4), sheet2!$H:$H, 0), COLUMN(F4))), "")} | I7: {=IFERROR(IF($A$4="", "", INDEX(sheet2!$A:$G, MATCH(ROW(G4), sheet2!$H:$H, 0), COLUMN(G4))), "")}
C8: {=IFERROR(IF($A$4="", "", INDEX(sheet2!$A:$H, MATCH(ROW(A5), sheet2!$H:$H, 0), COLUMN(A5))), "")} | D8: {=IFERROR(IF($A$4="", "", INDEX(sheet2!$A:$G, MATCH(ROW(B5), sheet2!$H:$H, 0), COLUMN(B5))), "")} | E8: {=IFERROR(IF($A$4="", "", INDEX(sheet2!$A:$G, MATCH(ROW(C5), sheet2!$H:$H, 0), COLUMN(C5))), "")} | F8: {=IFERROR(IF($A$4="", "", INDEX(sheet2!$A:$G, MATCH(ROW(D5), sheet2!$H:$H, 0), COLUMN(D5))), "")} | G8: {=IFERROR(IF($A$4="", "", INDEX(sheet2!$A:$G, MATCH(ROW(E5), sheet2!$H:$H, 0), COLUMN(E5))), "")} | H8: {=IFERROR(IF($A$4="", "", INDEX(sheet2!$A:$G, MATCH(ROW(F5), sheet2!$H:$H, 0), COLUMN(F5))), "")} | I8: {=IFERROR(IF($A$4="", "", INDEX(sheet2!$A:$G, MATCH(ROW(G5), sheet2!$H:$H, 0), COLUMN(G5))), "")}
C9: {=IFERROR(IF($A$4="", "", INDEX(sheet2!$A:$H, MATCH(ROW(A6), sheet2!$H:$H, 0), COLUMN(A6))), "")} | D9: {=IFERROR(IF($A$4="", "", INDEX(sheet2!$A:$G, MATCH(ROW(B6), sheet2!$H:$H, 0), COLUMN(B6))), "")} | E9: {=IFERROR(IF($A$4="", "", INDEX(sheet2!$A:$G, MATCH(ROW(C6), sheet2!$H:$H, 0), COLUMN(C6))), "")} | F9: {=IFERROR(IF($A$4="", "", INDEX(sheet2!$A:$G, MATCH(ROW(D6), sheet2!$H:$H, 0), COLUMN(D6))), "")} | G9: {=IFERROR(IF($A$4="", "", INDEX(sheet2!$A:$G, MATCH(ROW(E6), sheet2!$H:$H, 0), COLUMN(E6))), "")} | H9: {=IFERROR(IF($A$4="", "", INDEX(sheet2!$A:$G, MATCH(ROW(F6), sheet2!$H:$H, 0), COLUMN(F6))), "")} | I9: {=IFERROR(IF($A$4="", "", INDEX(sheet2!$A:$G, MATCH(ROW(G6), sheet2!$H:$H, 0), COLUMN(G6))), "")}
C10: {=IFERROR(IF($A$4="", "", INDEX(sheet2!$A:$H, MATCH(ROW(A7), sheet2!$H:$H, 0), COLUMN(A7))), "")} | D10: {=IFERROR(IF($A$4="", "", INDEX(sheet2!$A:$G, MATCH(ROW(B7), sheet2!$H:$H, 0), COLUMN(B7))), "")} | E10: {=IFERROR(IF($A$4="", "", INDEX(sheet2!$A:$G, MATCH(ROW(C7), sheet2!$H:$H, 0), COLUMN(C7))), "")} | F10: {=IFERROR(IF($A$4="", "", INDEX(sheet2!$A:$G, MATCH(ROW(D7), sheet2!$H:$H, 0), COLUMN(D7))), "")} | G10: {=IFERROR(IF($A$4="", "", INDEX(sheet2!$A:$G, MATCH(ROW(E7), sheet2!$H:$H, 0), COLUMN(E7))), "")} | H10: {=IFERROR(IF($A$4="", "", INDEX(sheet2!$A:$G, MATCH(ROW(F7), sheet2!$H:$H, 0), COLUMN(F7))), "")} | I10: {=IFERROR(IF($A$4="", "", INDEX(sheet2!$A:$G, MATCH(ROW(G7), sheet2!$H:$H, 0), COLUMN(G7))), "")}
C11: {=IFERROR(IF($A$4="", "", INDEX(sheet2!$A:$H, MATCH(ROW(A8), sheet2!$H:$H, 0), COLUMN(A8))), "")} | D11: {=IFERROR(IF($A$4="", "", INDEX(sheet2!$A:$G, MATCH(ROW(B8), sheet2!$H:$H, 0), COLUMN(B8))), "")} | E11: {=IFERROR(IF($A$4="", "", INDEX(sheet2!$A:$G, MATCH(ROW(C8), sheet2!$H:$H, 0), COLUMN(C8))), "")} | F11: {=IFERROR(IF($A$4="", "", INDEX(sheet2!$A:$G, MATCH(ROW(D8), sheet2!$H:$H, 0), COLUMN(D8))), "")} | G11: {=IFERROR(IF($A$4="", "", INDEX(sheet2!$A:$G, MATCH(ROW(E8), sheet2!$H:$H, 0), COLUMN(E8))), "")} | H11: {=IFERROR(IF($A$4="", "", INDEX(sheet2!$A:$G, MATCH(ROW(F8), sheet2!$H:$H, 0), COLUMN(F8))), "")} | I11: {=IFERROR(IF($A$4="", "", INDEX(sheet2!$A:$G, MATCH(ROW(G8), sheet2!$H:$H, 0), COLUMN(G8))), "")}
C12: {=IFERROR(IF($A$4="", "", INDEX(sheet2!$A:$H, MATCH(ROW(A9), sheet2!$H:$H, 0), COLUMN(A9))), "")} | D12: {=IFERROR(IF($A$4="", "", INDEX(sheet2!$A:$G, MATCH(ROW(B9), sheet2!$H:$H, 0), COLUMN(B9))), "")} | E12: {=IFERROR(IF($A$4="", "", INDEX(sheet2!$A:$G, MATCH(ROW(C9), sheet2!$H:$H, 0), COLUMN(C9))), "")} | F12: {=IFERROR(IF($A$4="", "", INDEX(sheet2!$A:$G, MATCH(ROW(D9), sheet2!$H:$H, 0), COLUMN(D9))), "")} | G12: {=IFERROR(IF($A$4="", "", INDEX(sheet2!$A:$G, MATCH(ROW(E9), sheet2!$H:$H, 0), COLUMN(E9))), "")} | H12: {=IFERROR(IF($A$4="", "", INDEX(sheet2!$A:$G, MATCH(ROW(F9), sheet2!$H:$H, 0), COLUMN(F9))), "")} | I12: {=IFERROR(IF($A$4="", "", INDEX(sheet2!$A:$G, MATCH(ROW(G9), sheet2!$H:$H, 0), COLUMN(G9))), "")}
C13: {=IFERROR(IF($A$4="", "", INDEX(sheet2!$A:$H, MATCH(ROW(A10), sheet2!$H:$H, 0), COLUMN(A10))), "")} | D13: {=IFERROR(IF($A$4="", "", INDEX(sheet2!$A:$G, MATCH(ROW(B10), sheet2!$H:$H, 0), COLUMN(B10))), "")} | E13: {=IFERROR(IF($A$4="", "", INDEX(sheet2!$A:$G, MATCH(ROW(C10), sheet2!$H:$H, 0), COLUMN(C10))), "")} | F13: {=IFERROR(IF($A$4="", "", INDEX(sheet2!$A:$G, MATCH(ROW(D10), sheet2!$H:$H, 0), COLUMN(D10))), "")} | G13: {=IFERROR(IF($A$4="", "", INDEX(sheet2!$A:$G, MATCH(ROW(E10), sheet2!$H:$H, 0), COLUMN(E10))), "")} | H13: {=IFERROR(IF($A$4="", "", INDEX(sheet2!$A:$G, MATCH(ROW(F10), sheet2!$H:$H, 0), COLUMN(F10))), "")} | I13: {=IFERROR(IF($A$4="", "", INDEX(sheet2!$A:$G, MATCH(ROW(G10), sheet2!$H:$H, 0), COLUMN(G10))), "")}
C14: {=IFERROR(IF($A$4="", "", INDEX(sheet2!$A:$H, MATCH(ROW(A11), sheet2!$H:$H, 0), COLUMN(A11))), "")} | D14: {=IFERROR(IF($A$4="", "", INDEX(sheet2!$A:$G, MATCH(ROW(B11), sheet2!$H:$H, 0), COLUMN(B11))), "")} | E14: {=IFERROR(IF($A$4="", "", INDEX(sheet2!$A:$G, MATCH(ROW(C11), sheet2!$H:$H, 0), COLUMN(C11))), "")} | F14: {=IFERROR(IF($A$4="", "", INDEX(sheet2!$A:$G, MATCH(ROW(D11), sheet2!$H:$H, 0), COLUMN(D11))), "")} | G14: {=IFERROR(IF($A$4="", "", INDEX(sheet2!$A:$G, MATCH(ROW(E11), sheet2!$H:$H, 0), COLUMN(E11))), "")} | H14: {=IFERROR(IF($A$4="", "", INDEX(sheet2!$A:$G, MATCH(ROW(F11), sheet2!$H:$H, 0), COLUMN(F11))), "")} | I14: {=IFERROR(IF($A$4="", "", INDEX(sheet2!$A:$G, MATCH(ROW(G11), sheet2!$H:$H, 0), COLUMN(G11))), "")}
C15: {=IFERROR(IF($A$4="", "", INDEX(sheet2!$A:$H, MATCH(ROW(A12), sheet2!$H:$H, 0), COLUMN(A12))), "")} | D15: {=IFERROR(IF($A$4="", "", INDEX(sheet2!$A:$G, MATCH(ROW(B12), sheet2!$H:$H, 0), COLUMN(B12))), "")} | E15: {=IFERROR(IF($A$4="", "", INDEX(sheet2!$A:$G, MATCH(ROW(C12), sheet2!$H:$H, 0), COLUMN(C12))), "")} | F15: {=IFERROR(IF($A$4="", "", INDEX(sheet2!$A:$G, MATCH(ROW(D12), sheet2!$H:$H, 0), COLUMN(D12))), "")} | G15: {=IFERROR(IF($A$4="", "", INDEX(sheet2!$A:$G, MATCH(ROW(E12), sheet2!$H:$H, 0), COLUMN(E12))), "")} | H15: {=IFERROR(IF($A$4="", "", INDEX(sheet2!$A:$G, MATCH(ROW(F12), sheet2!$H:$H, 0), COLUMN(F12))), "")} | I15: {=IFERROR(IF($A$4="", "", INDEX(sheet2!$A:$G, MATCH(ROW(G12), sheet2!$H:$H, 0), COLUMN(G12))), "")}
... C30: {=IFERROR(IF($A$4="", "", INDEX(sheet2!$A:$H, MATCH(ROW(A27), sheet2!$H:$H, 0), COLUMN(A27))), "")} | D30: {=IFERROR(IF($A$4="", "", INDEX(sheet2!$A:$G, MATCH(ROW(B27), sheet2!$H:$H, 0), COLUMN(B27))), "")} | E30: {=IFERROR(IF($A$4="", "", INDEX(sheet2!$A:$G, MATCH(ROW(C27), sheet2!$H:$H, 0), COLUMN(C27))), "")} | F30: {=IFERROR(IF($A$4="", "", INDEX(sheet2!$A:$G, MATCH(ROW(D27), sheet2!$H:$H, 0), COLUMN(D27))), "")} | G30: {=IFERROR(IF($A$4="", "", INDEX(sheet2!$A:$G, MATCH(ROW(E27), sheet2!$H:$H, 0), COLUMN(E27))), "")} | H30: {=IFERROR(IF($A$4="", "", INDEX(sheet2!$A:$G, MATCH(ROW(F27), sheet2!$H:$H, 0), COLUMN(F27))), "")} | I30: {=IFERROR(IF($A$4="", "", INDEX(sheet2!$A:$G, MATCH(ROW(G27), sheet2!$H:$H, 0), COLUMN(G27))), "")}

Sheet sheet2
A1: 棚 | B1: 段 | C1: 書籍名 | D1: 著者名 | E1: 出版社 | F1: 年 | G1: 備考 | H1: 作業列
A2: B | B2: 1 | C2: 智光曼荼羅 | D2: 元興寺仏教民族資料刊行会 | E2: 学術書出版会 | F2: 1969 | H2: =IF(OR(A2="", sheet1!A$4=""), "", IF(SUM(COUNTIF(A2, "*"&sheet1!A$4&"*"), COUNTIF(B2, "*"&sheet1!A$4&"*"), COUNTIF(C2, "*"&sheet1!A$4&"*"), COUNTIF(D2, "*"&sheet1!A$4&"*"), COUNTIF(E2, "*"&sheet1!A$4&"*"), COUNTIF(F2, "*"&sheet1!A$4&"*"), COUNTIF(G2, "*"&sheet1!A$4&"*")) > 0, MAX(H$1:H1)+1, ""))
A3: B | B3: 1 | C3: 仏教図像聚成 | D3: 京都市立芸術大学芸術資料館 | E3: 法蔵館 | F3: 2004 | H3: =IF(OR(A3="", sheet1!A$4=""), "", IF(SUM(COUNTIF(A3, "*"&sheet1!A$4&"*"), COUNTIF(B3, "*"&sheet1!A$4&"*"), COUNTIF(C3, "*"&sheet1!A$4&"*"), COUNTIF(D3, "*"&sheet1!A$4&"*"), COUNTIF(E3, "*"&sheet1!A$4&"*"), COUNTIF(F3, "*"&sheet1!A$4&"*"), COUNTIF(G3, "*"&sheet1!A$4&"*")) > 0, MAX(H$1:H2)+1, ""))
A4: B | B4: 1 | C4: 日本の名画1 近世絵画Ⅰ | E4: ほるぷ出版 | F4: 1975 | H4: =IF(OR(A4="", sheet1!A$4=""), "", IF(SUM(COUNTIF(A4, "*"&sheet1!A$4&"*"), COUNTIF(B4, "*"&sheet1!A$4&"*"), COUNTIF(C4, "*"&sheet1!A$4&"*"), COUNTIF(D4, "*"&sheet1!A$4&"*"), COUNTIF(E4, "*"&sheet1!A$4&"*"), COUNTIF(F4, "*"&sheet1!A$4&"*"), COUNTIF(G4, "*"&sheet1!A$4&"*")) > 0, MAX(H$1:H3)+1, ""))
A5: B | B5: 1 | C5: 古面 | D5: 京都国立博物館 | E5: 岩波書店 | F5: 1982 | H5: =IF(OR(A5="", sheet1!A$4=""), "", IF(SUM(COUNTIF(A5, "*"&sheet1!A$4&"*"), COUNTIF(B5, "*"&sheet1!A$4&"*"), COUNTIF(C5, "*"&sheet1!A$4&"*"), COUNTIF(D5, "*"&sheet1!A$4&"*"), COUNTIF(E5, "*"&sheet1!A$4&"*"), COUNTIF(F5, "*"&sheet1!A$4&"*"), COUNTIF(G5, "*"&sheet1!A$4&"*")) > 0, MAX(H$1:H4)+1, ""))
A6: B | B6: 1 | C6: 慈恩大師御影聚英 | D6: 興福寺・薬師寺 | E6: 法蔵館 | F6: 1982 | H6: =IF(OR(A6="", sheet1!A$4=""), "", IF(SUM(COUNTIF(A6, "*"&sheet1!A$4&"*"), COUNTIF(B6, "*"&sheet1!A$4&"*"), COUNTIF(C6, "*"&sheet1!A$4&"*"), COUNTIF(D6, "*"&sheet1!A$4&"*"), COUNTIF(E6, "*"&sheet1!A$4&"*"), COUNTIF(F6, "*"&sheet1!A$4&"*"), COUNTIF(G6, "*"&sheet1!A$4&"*")) > 0, MAX(H$1:H5)+1, ""))
A7: B | B7: 1 | C7: 古代小金銅仏 | D7: 久野健 | E7: 小学館 | F7: 1982 | H7: =IF(OR(A7="", sheet1!A$4=""), "", IF(SUM(COUNTIF(A7, "*"&sheet1!A$4&"*"), COUNTIF(B7, "*"&sheet1!A$4&"*"), COUNTIF(C7, "*"&sheet1!A$4&"*"), COUNTIF(D7, "*"&sheet1!A$4&"*"), COUNTIF(E7, "*"&sheet1!A$4&"*"), COUNTIF(F7, "*"&sheet1!A$4&"*"), COUNTIF(G7, "*"&sheet1!A$4&"*")) > 0, MAX(H$1:H6)+1, ""))
A8: B | B8: 1 | C8: 日本仏教美術の源流Ⅰ 彫刻・考古篇 | D8: 奈良国立博物館 | E8: 同朋舎出版 | F8: 1984 | H8: =IF(OR(A8="", sheet1!A$4=""), "", IF(SUM(COUNTIF(A8, "*"&sheet1!A$4&"*"), COUNTIF(B8, "*"&sheet1!A$4&"*"), COUNTIF(C8, "*"&sheet1!A$4&"*"), COUNTIF(D8, "*"&sheet1!A$4&"*"), COUNTIF(E8, "*"&sheet1!A$4&"*"), COUNTIF(F8, "*"&sheet1!A$4&"*"), COUNTIF(G8, "*"&sheet1!A$4&"*")) > 0, MAX(H$1:H7)+1, ""))
A9: B | B9: 1 | C9: 日本仏教美術の源流Ⅱ 絵画・工芸・書蹟篇 | D9: 奈良国立博物館 | E9: 同朋舎出版 | F9: 1984 | H9: =IF(OR(A9="", sheet1!A$4=""), "", IF(SUM(COUNTIF(A9, "*"&sheet1!A$4&"*"), COUNTIF(B9, "*"&sheet1!A$4&"*"), COUNTIF(C9, "*"&sheet1!A$4&"*"), COUNTIF(D9, "*"&sheet1!A$4&"*"), COUNTIF(E9, "*"&sheet1!A$4&"*"), COUNTIF(F9, "*"&sheet1!A$4&"*"), COUNTIF(G9, "*"&sheet1!A$4&"*")) > 0, MAX(H$1:H8)+1, ""))
A10: B | B10: 1 | C10: 鏡像 | D10: 東京国立博物館 | E10: 至文堂 | F10: 1975 | H10: =IF(OR(A10="", sheet1!A$4=""), "", IF(SUM(COUNTIF(A10, "*"&sheet1!A$4&"*"), COUNTIF(B10, "*"&sheet1!A$4&"*"), COUNTIF(C10, "*"&sheet1!A$4&"*"), COUNTIF(D10, "*"&sheet1!A$4&"*"), COUNTIF(E10, "*"&sheet1!A$4&"*"), COUNTIF(F10, "*"&sheet1!A$4&"*"), COUNTIF(G10, "*"&sheet1!A$4&"*")) > 0, MAX(H$1:H9)+1, ""))
A11: B | B11: 1 | C11: 密教法具 | D11: 奈良国立博物館 | E11: 講談社 | F11: 1965 | H11: =IF(OR(A11="", sheet1!A$4=""), "", IF(SUM(COUNTIF(A11, "*"&sheet1!A$4&"*"), COUNTIF(B11, "*"&sheet1!A$4&"*"), COUNTIF(C11, "*"&sheet1!A$4&"*"), COUNTIF(D11, "*"&sheet1!A$4&"*"), COUNTIF(E11, "*"&sheet1!A$4&"*"), COUNTIF(F11, "*"&sheet1!A$4&"*"), COUNTIF(G11, "*"&sheet1!A$4&"*")) > 0, MAX(H$1:H10)+1, ""))
A12: B | B12: 1 | C12: 仏舎利の荘厳 | D12: 奈良国立博物館 | E12: 同朋舎出版 | F12: 1983 | H12: =IF(OR(A12="", sheet1!A$4=""), "", IF(SUM(COUNTIF(A12, "*"&sheet1!A$4&"*"), COUNTIF(B12, "*"&sheet1!A$4&"*"), COUNTIF(C12, "*"&sheet1!A$4&"*"), COUNTIF(D12, "*"&sheet1!A$4&"*"), COUNTIF(E12, "*"&sheet1!A$4&"*"), COUNTIF(F12, "*"&sheet1!A$4&"*"), COUNTIF(G12, "*"&sheet1!A$4&"*")) > 0, MAX(H$1:H11)+1, ""))
A13: B | B13: 1 | C13: 経塚遺宝 | D13: 奈良国立博物館 | E13: 東京美術 | F13: 1977 | H13: =IF(OR(A13="", sheet1!A$4=""), "", IF(SUM(COUNTIF(A13, "*"&sheet1!A$4&"*"), COUNTIF(B13, "*"&sheet1!A$4&"*"), COUNTIF(C13, "*"&sheet1!A$4&"*"), COUNTIF(D13, "*"&sheet1!A$4&"*"), COUNTIF(E13, "*"&sheet1!A$4&"*"), COUNTIF(F13, "*"&sheet1!A$4&"*"), COUNTIF(G13, "*"&sheet1!A$4&"*")) > 0, MAX(H$1:H12)+1, ""))
A14: B | B14: 1 | C14: 金銅仏 中国・朝鮮・日本 | D14: 東京国立博物館 | E14: 大塚巧芸社 | F14: 1988 | H14: =IF(OR(A14="", sheet1!A$4=""), "", IF(SUM(COUNTIF(A14, "*"&sheet1!A$4&"*"), COUNTIF(B14, "*"&sheet1!A$4&"*"), COUNTIF(C14, "*"&sheet1!A$4&"*"), COUNTIF(D14, "*"&sheet1!A$4&"*"), COUNTIF(E14, "*"&sheet1!A$4&"*"), COUNTIF(F14, "*"&sheet1!A$4&"*"), COUNTIF(G14, "*"&sheet1!A$4&"*")) > 0, MAX(H$1:H13)+1, ""))
A15: B | B15: 1 | C15: 小金銅仏 | D15: 松原三郎・田辺三郎助 | E15: 東京美術 | F15: 1979 | H15: =IF(OR(A15="", sheet1!A$4=""), "", IF(SUM(COUNTIF(A15, "*"&sheet1!A$4&"*"), COUNTIF(B15, "*"&sheet1!A$4&"*"), COUNTIF(C15, "*"&sheet1!A$4&"*"), COUNTIF(D15, "*"&sheet1!A$4&"*"), COUNTIF(E15, "*"&sheet1!A$4&"*"), COUNTIF(F15, "*"&sheet1!A$4&"*"), COUNTIF(G15, "*"&sheet1!A$4&"*")) > 0, MAX(H$1:H14)+1, ""))
A16: B | B16: 1 | C16: 唐招提寺古経選 | D16: 栗本和夫 | E16: 中央公論美術出版 | F16: 1975 | H16: =IF(OR(A16="", sheet1!A$4=""), "", IF(SUM(COUNTIF(A16, "*"&sheet1!A$4&"*"), COUNTIF(B16, "*"&sheet1!A$4&"*"), COUNTIF(C16, "*"&sheet1!A$4&"*"), COUNTIF(D16, "*"&sheet1!A$4&"*"), COUNTIF(E16, "*"&sheet1!A$4&"*"), COUNTIF(F16, "*"&sheet1!A$4&"*"), COUNTIF(G16, "*"&sheet1!A$4&"*")) > 0, MAX(H$1:H15)+1, ""))
... A18: B | B18: 1 | C18: 藤原美術聚英 | D18: 帝室博物館 | E18: 便利堂 | F18: 1937 | H18: =IF(OR(A18="", sheet1!A$4=""), "", IF(SUM(COUNTIF(A18, "*"&sheet1!A$4&"*"), COUNTIF(B18, "*"&sheet1!A$4&"*"), COUNTIF(C18, "*"&sheet1!A$4&"*"), COUNTIF(D18, "*"&sheet1!A$4&"*"), COUNTIF(E18, "*"&sheet1!A$4&"*"), COUNTIF(F18, "*"&sheet1!A$4&"*"), COUNTIF(G18, "*"&sheet1!A$4&"*")) > 0, MAX(H$1:H17)+1, ""))
H19: =IF(OR(A19="", sheet1!A$4=""), "", IF(SUM(COUNTIF(A19, "*"&sheet1!A$4&"*"), COUNTIF(B19, "*"&sheet1!A$4&"*"), COUNTIF(C19, "*"&sheet1!A$4&"*"), COUNTIF(D19, "*"&sheet1!A$4&"*"), COUNTIF(E19, "*"&sheet1!A$4&"*"), COUNTIF(F19, "*"&sheet1!A$4&"*"), COUNTIF(G19, "*"&sheet1!A$4&"*")) > 0, MAX(H$1:H18)+1, ""))
A20: B | B20: 2 | C20: 極楽絵 | D20: 真保亨 | E20: 毎日新聞社 | F20: 1977 | H20: =IF(OR(A20="", sheet1!A$4=""), "", IF(SUM(COUNTIF(A20, "*"&sheet1!A$4&"*"), COUNTIF(B20, "*"&sheet1!A$4&"*"), COUNTIF(C20, "*"&sheet1!A$4&"*"), COUNTIF(D20, "*"&sheet1!A$4&"*"), COUNTIF(E20, "*"&sheet1!A$4&"*"), COUNTIF(F20, "*"&sheet1!A$4&"*"), COUNTIF(G20, "*"&sheet1!A$4&"*")) > 0, MAX(H$1:H19)+1, ""))
A21: B | B21: 2 | C21: 六道絵 | D21: 真保亨 | E21: 毎日新聞社 | F21: 1977 | H21: =IF(OR(A21="", sheet1!A$4=""), "", IF(SUM(COUNTIF(A21, "*"&sheet1!A$4&"*"), COUNTIF(B21, "*"&sheet1!A$4&"*"), COUNTIF(C21, "*"&sheet1!A$4&"*"), COUNTIF(D21, "*"&sheet1!A$4&"*"), COUNTIF(E21, "*"&sheet1!A$4&"*"), COUNTIF(F21, "*"&sheet1!A$4&"*"), COUNTIF(G21, "*"&sheet1!A$4&"*")) > 0, MAX(H$1:H20)+1, ""))
A22: B | B22: 2 | C22: 仏伝図 | D22: 真保亨 | E22: 毎日新聞社 | F22: 1978 | H22: =IF(OR(A22="", sheet1!A$4=""), "", IF(SUM(COUNTIF(A22, "*"&sheet1!A$4&"*"), COUNTIF(B22, "*"&sheet1!A$4&"*"), COUNTIF(C22, "*"&sheet1!A$4&"*"), COUNTIF(D22, "*"&sheet1!A$4&"*"), COUNTIF(E22, "*"&sheet1!A$4&"*"), COUNTIF(F22, "*"&sheet1!A$4&"*"), COUNTIF(G22, "*"&sheet1!A$4&"*")) > 0, MAX(H$1:H21)+1, ""))
A23: B | B23: 2 | C23: 来迎図の美術 | D23: 中野玄三 | E23: 同朋舎出版 | F23: 1985 | H23: =IF(OR(A23="", sheet1!A$4=""), "", IF(SUM(COUNTIF(A23, "*"&sheet1!A$4&"*"), COUNTIF(B23, "*"&sheet1!A$4&"*"), COUNTIF(C23, "*"&sheet1!A$4&"*"), COUNTIF(D23, "*"&sheet1!A$4&"*"), COUNTIF(E23, "*"&sheet1!A$4&"*"), COUNTIF(F23, "*"&sheet1!A$4&"*"), COUNTIF(G23, "*"&sheet1!A$4&"*")) > 0, MAX(H$1:H22)+1, ""))
A24: B | B24: 2 | C24: 来迎図の美術 増補版 | D24: 中野玄三 | E24: 同朋舎出版 | F24: 2013 | H24: =IF(OR(A24="", sheet1!A$4=""), "", IF(SUM(COUNTIF(A24, "*"&sheet1!A$4&"*"), COUNTIF(B24, "*"&sheet1!A$4&"*"), COUNTIF(C24, "*"&sheet1!A$4&"*"), COUNTIF(D24, "*"&sheet1!A$4&"*"), COUNTIF(E24, "*"&sheet1!A$4&"*"), COUNTIF(F24, "*"&sheet1!A$4&"*"), COUNTIF(G24, "*"&sheet1!A$4&"*")) > 0, MAX(H$1:H23)+1, ""))
A25: B | B25: 2 | C25: 来迎図の美術 | D25: 中野玄三 | E25: 同朋舎出版 | F25: 2013 | H25: =IF(OR(A25="", sheet1!A$4=""), "", IF(SUM(COUNTIF(A25, "*"&sheet1!A$4&"*"), COUNTIF(B25, "*"&sheet1!A$4&"*"), COUNTIF(C25, "*"&sheet1!A$4&"*"), COUNTIF(D25, "*"&sheet1!A$4&"*"), COUNTIF(E25, "*"&sheet1!A$4&"*"), COUNTIF(F25, "*"&sheet1!A$4&"*"), COUNTIF(G25, "*"&sheet1!A$4&"*")) > 0, MAX(H$1:H24)+1, ""))
A26: B | B26: 2 | C26: 仏教説話の美術 | D26: 奈良国立博物館 | E26: 思文閣出版 | F26: 1996 | H26: =IF(OR(A26="", sheet1!A$4=""), "", IF(SUM(COUNTIF(A26, "*"&sheet1!A$4&"*"), COUNTIF(B26, "*"&sheet1!A$4&"*"), COUNTIF(C26, "*"&sheet1!A$4&"*"), COUNTIF(D26, "*"&sheet1!A$4&"*"), COUNTIF(E26, "*"&sheet1!A$4&"*"), COUNTIF(F26, "*"&sheet1!A$4&"*"), COUNTIF(G26, "*"&sheet1!A$4&"*")) > 0, MAX(H$1:H25)+1, ""))
A27: B | B27: 2 | C27: 地獄絵 | D27: 真保亨 | E27: 毎日新聞社 | F27: 1976 | H27: =IF(OR(A27="", sheet1!A$4=""), "", IF(SUM(COUNTIF(A27, "*"&sheet1!A$4&"*"), COUNTIF(B27, "*"&sheet1!A$4&"*"), COUNTIF(C27, "*"&sheet1!A$4&"*"), COUNTIF(D27, "*"&sheet1!A$4&"*"), COUNTIF(E27, "*"&sheet1!A$4&"*"), COUNTIF(F27, "*"&sheet1!A$4&"*"), COUNTIF(G27, "*"&sheet1!A$4&"*")) > 0, MAX(H$1:H26)+1, ""))
A28: B | B28: 2 | C28: 国宝 六道絵 | D28: 泉武夫・加須屋誠・山本聡美 | E28: 中央公論美術出版 | F28: 2007 | G28: スキャン用バラ | H28: =IF(OR(A28="", sheet1!A$4=""), "", IF(SUM(COUNTIF(A28, "*"&sheet1!A$4&"*"), COUNTIF(B28, "*"&sheet1!A$4&"*"), COUNTIF(C28, "*"&sheet1!A$4&"*"), COUNTIF(D28, "*"&sheet1!A$4&"*"), COUNTIF(E28, "*"&sheet1!A$4&"*"), COUNTIF(F28, "*"&sheet1!A$4&"*"), COUNTIF(G28, "*"&sheet1!A$4&"*")) > 0, MAX(H$1:H27)+1, ""))
A29: B | B29: 2 | C29: 国宝 六道絵 | D29: 泉武夫・加須屋誠・山本聡美 | E29: 中央公論美術出版 | F29: 2007 | H29: =IF(OR(A29="", sheet1!A$4=""), "", IF(SUM(COUNTIF(A29, "*"&sheet1!A$4&"*"), COUNTIF(B29, "*"&sheet1!A$4&"*"), COUNTIF(C29, "*"&sheet1!A$4&"*"), COUNTIF(D29, "*"&sheet1!A$4&"*"), COUNTIF(E29, "*"&sheet1!A$4&"*"), COUNTIF(F29, "*"&sheet1!A$4&"*"), COUNTIF(G29, "*"&sheet1!A$4&"*")) > 0, MAX(H$1:H28)+1, ""))
A30: B | B30: 2 | C30: 病草紙 | D30: 加須屋誠・山本聡美 | E30: 中央公論美術出版 | F30: 2017 | H30: =IF(OR(A30="", sheet1!A$4=""), "", IF(SUM(COUNTIF(A30, "*"&sheet1!A$4&"*"), COUNTIF(B30, "*"&sheet1!A$4&"*"), COUNTIF(C30, "*"&sheet1!A$4&"*"), COUNTIF(D30, "*"&sheet1!A$4&"*"), COUNTIF(E30, "*"&sheet1!A$4&"*"), COUNTIF(F30, "*"&sheet1!A$4&"*"), COUNTIF(G30, "*"&sheet1!A$4&"*")) > 0, MAX(H$1:H29)+1, ""))
A31: B | B31: 2 | C31: 杏雨書屋所蔵 病草紙 模本集成 | D31: 武田科学振興財団 | E31: 武田科学振興財団 | F31: 2017 | H31: =IF(OR(A31="", sheet1!A$4=""), "", IF(SUM(COUNTIF(A31, "*"&sheet1!A$4&"*"), COUNTIF(B31, "*"&sheet1!A$4&"*"), COUNTIF(C31, "*"&sheet1!A$4&"*"), COUNTIF(D31, "*"&sheet1!A$4&"*"), COUNTIF(E31, "*"&sheet1!A$4&"*"), COUNTIF(F31, "*"&sheet1!A$4&"*"), COUNTIF(G31, "*"&sheet1!A$4&"*")) > 0, MAX(H$1:H30)+1, ""))
A32: B | B32: 2 | C32: 国宝 応徳仏涅槃図の研究と保存 | D32: 高野山文化財保存会 | E32: 東京美術 | F32: 1983 | G32: 上・下2巻あり | H32: =IF(OR(A32="", sheet1!A$4=""), "", IF(SUM(COUNTIF(A32, "*"&sheet1!A$4&"*"), COUNTIF(B32, "*"&sheet1!A$4&"*"), COUNTIF(C32, "*"&sheet1!A$4&"*"), COUNTIF(D32, "*"&sheet1!A$4&"*"), COUNTIF(E32, "*"&sheet1!A$4&"*"), COUNTIF(F32, "*"&sheet1!A$4&"*"), COUNTIF(G32, "*"&sheet1!A$4&"*")) > 0, MAX(H$1:H31)+1, ""))
A33: B | B33: 2 | C33: 国宝 釈迦金棺出現図 京都国立博物館蔵 | D33: 京都国立博物館 | E33: 便利堂 | F33: 1992 | H33: =IF(OR(A33="", sheet1!A$4=""), "", IF(SUM(COUNTIF(A33, "*"&sheet1!A$4&"*"), COUNTIF(B33, "*"&sheet1!A$4&"*"), COUNTIF(C33, "*"&sheet1!A$4&"*"), COUNTIF(D33, "*"&sheet1!A$4&"*"), COUNTIF(E33, "*"&sheet1!A$4&"*"), COUNTIF(F33, "*"&sheet1!A$4&"*"), COUNTIF(G33, "*"&sheet1!A$4&"*")) > 0, MAX(H$1:H32)+1, ""))
A34: B | B34: 2 | C34: 釈迦金棺出現図 | D34: 田中一松・山口蓬春 | E34: 美術出版社 | F34: 1957 | H34: =IF(OR(A34="", sheet1!A$4=""), "", IF(SUM(COUNTIF(A34, "*"&sheet1!A$4&"*"), COUNTIF(B34, "*"&sheet1!A$4&"*"), COUNTIF(C34, "*"&sheet1!A$4&"*"), COUNTIF(D34, "*"&sheet1!A$4&"*"), COUNTIF(E34, "*"&sheet1!A$4&"*"), COUNTIF(F34, "*"&sheet1!A$4&"*"), COUNTIF(G34, "*"&sheet1!A$4&"*")) > 0, MAX(H$1:H33)+1, ""))
A35: B | B35: 2 | C35: 京都国立博物館蔵 興福寺曼荼羅図 | D35: 京都国立博物館 | E35: 便利堂 | F35: 1995 | H35: =IF(OR(A35="", sheet1!A$4=""), "", IF(SUM(COUNTIF(A35, "*"&sheet1!A$4&"*"), COUNTIF(B35, "*"&sheet1!A$4&"*"), COUNTIF(C35, "*"&sheet1!A$4&"*"), COUNTIF(D35, "*"&sheet1!A$4&"*"), COUNTIF(E35, "*"&sheet1!A$4&"*"), COUNTIF(F35, "*"&sheet1!A$4&"*"), COUNTIF(G35, "*"&sheet1!A$4&"*")) > 0, MAX(H$1:H34)+1, ""))
A36: B | B36: 2 | C36: 社寺参詣曼荼羅 | D36: 大阪市立博物館 | E36: 平凡社 | F36: 1987 | H36: =IF(OR(A36="", sheet1!A$4=""), "", IF(SUM(COUNTIF(A36, "*"&sheet1!A$4&"*"), COUNTIF(B36, "*"&sheet1!A$4&"*"), COUNTIF(C36, "*"&sheet1!A$4&"*"), COUNTIF(D36, "*"&sheet1!A$4&"*"), COUNTIF(E36, "*"&sheet1!A$4&"*"), COUNTIF(F36, "*"&sheet1!A$4&"*"), COUNTIF(G36, "*"&sheet1!A$4&"*")) > 0, MAX(H$1:H35)+1, ""))
A37: B | B37: 2 | C37: 聖徳太子絵伝 | D37: 奈良国立博物館 | E37: 東京美術 | F37: 1969 | H37: =IF(OR(A37="", sheet1!A$4=""), "", IF(SUM(COUNTIF(A37, "*"&sheet1!A$4&"*"), COUNTIF(B37, "*"&sheet1!A$4&"*"), COUNTIF(C37, "*"&sheet1!A$4&"*"), COUNTIF(D37, "*"&sheet1!A$4&"*"), COUNTIF(E37, "*"&sheet1!A$4&"*"), COUNTIF(F37, "*"&sheet1!A$4&"*"), COUNTIF(G37, "*"&sheet1!A$4&"*")) > 0, MAX(H$1:H36)+1, ""))
A38: B | B38: 2 | C38: 聖徳太子尊像聚成 図版編 | D38: 石田茂作 | E38: 講談社 | F38: 1976 | H38: =IF(OR(A38="", sheet1!A$4=""), "", IF(SUM(COUNTIF(A38, "*"&sheet1!A$4&"*"), COUNTIF(B38, "*"&sheet1!A$4&"*"), COUNTIF(C38, "*"&sheet1!A$4&"*"), COUNTIF(D38, "*"&sheet1!A$4&"*"), COUNTIF(E38, "*"&sheet1!A$4&"*"), COUNTIF(F38, "*"&sheet1!A$4&"*"), COUNTIF(G38, "*"&sheet1!A$4&"*")) > 0, MAX(H$1:H37)+1, ""))
A39: B | B39: 2 | C39: 聖徳太子尊像聚成 | D39: 石田茂作 | E39: 講談社 | F39: 1976 | H39: =IF(OR(A39="", sheet1!A$4=""), "", IF(SUM(COUNTIF(A39, "*"&sheet1!A$4&"*"), COUNTIF(B39, "*"&sheet1!A$4&"*"), COUNTIF(C39, "*"&sheet1!A$4&"*"), COUNTIF(D39, "*"&sheet1!A$4&"*"), COUNTIF(E39, "*"&sheet1!A$4&"*"), COUNTIF(F39, "*"&sheet1!A$4&"*"), COUNTIF(G39, "*"&sheet1!A$4&"*")) > 0, MAX(H$1:H38)+1, ""))
A40: B | B40: 2 | C40: 王朝の仏画と儀礼 | D40: 京都国立博物館 | E40: 至文堂 | F40: 2000 | H40: =IF(OR(A40="", sheet1!A$4=""), "", IF(SUM(COUNTIF(A40, "*"&sheet1!A$4&"*"), COUNTIF(B40, "*"&sheet1!A$4&"*"), COUNTIF(C40, "*"&sheet1!A$4&"*"), COUNTIF(D40, "*"&sheet1!A$4&"*"), COUNTIF(E40, "*"&sheet1!A$4&"*"), COUNTIF(F40, "*"&sheet1!A$4&"*"), COUNTIF(G40, "*"&sheet1!A$4&"*")) > 0, MAX(H$1:H39)+1, ""))
A41: B | B41: 2 | C41: 聖徳太子信仰の美術 | D41: 大阪市立美術館 | E41: 東方出版 | F41: 1996 | H41: =IF(OR(A41="", sheet1!A$4=""), "", IF(SUM(COUNTIF(A41, "*"&sheet1!A$4&"*"), COUNTIF(B41, "*"&sheet1!A$4&"*"), COUNTIF(C41, "*"&sheet1!A$4&"*"), COUNTIF(D41, "*"&sheet1!A$4&"*"), COUNTIF(E41, "*"&sheet1!A$4&"*"), COUNTIF(F41, "*"&sheet1!A$4&"*"), COUNTIF(G41, "*"&sheet1!A$4&"*")) > 0, MAX(H$1:H40)+1, ""))
...

Sheet 1-A
A1: 書籍・図録名 | B1: 著者名 | C1: 出版社・開催館 | D1: 年 | E1: 備考 | G1: 書籍・図録名 | H1: 著者名 | I1: 出版社・開催館 | J1: 年 | K1: 備考 | M1: 書籍・図録名 | N1: 著者名 | O1: 出版社・開催館 | P1: 年 | Q1: 備考
A2: 1段目 | B2: ※1~5段目は『日本の美術』が揃っている。別ファイル参照 | G2: 2段目 | M2: 6段目(研究報告書が中心)
A3: 日本の美術1 | G3: 日本の美術101 | M3: （過去の発表資料）
A4: 日本の美術2 | G4: 日本の美術102 | M4: 平泉 中尊寺・毛越寺の全容 | N4: 藤島亥治郎(監修) | O4: 川嶋印刷株式会社 | P4: 1991
A5: 日本の美術3 | G5: 日本の美術103 | M5: 亀田鵬斎碑文並びに序跋訳注集成 | N5: 守屋正彦(責任編集)ほか | O5: 筑波大学日本美術史研究室 | P5: 2010
A6: 日本の美術4 | G6: 日本の美術104 | M6: 中世寺社境内の風景 | N6: 泉万里 | P6: 2022
A7: 日本の美術5 | G7: 日本の美術105 | M7: 絹織製作技術 | N7: 東京文化財研究所 | O7: 東京文化財研究所 | P7: 2021
A8: 日本の美術6 | G8: 日本の美術106 | M8: 文化財修理の最先端 | N8: 京都国立博物館 | O8: 京都国立博物館 | P8: 2020
A9: 日本の美術7 | G9: 日本の美術107 | M9: 京都市立芸術大学芸術資料館所蔵 中国書画録 | N9: 竹浪遠 | O9: 京都市立芸術大学 | P9: 2021
A10: 日本の美術8 | G10: 日本の美術108 | M10: 20世紀の女性美術家と視覚表象の調査研究 | N10: 北原恵 | O10: 大阪大学文学研究科・日本学研究室 | P10: 2011
A11: 日本の美術9 | G11: 日本の美術109 | M11: 令和四年度 奈良国立博物館 文化財保存修理所 修理報告書 第六号 | N11: 奈良国立博物館 | O11: 奈良国立博物館 | P11: 2024
A12: 日本の美術10 | G12: 日本の美術110 | M12: 令和二年度 京都国立博物館 文化財保存修理所 修理報告書 21 | N12: 京都国立博物館 | O12: 京都国立博物館 | P12: 2024
A13: 日本の美術11 | G13: 日本の美術111 | M13: 令和元年度 京都国立博物館 文化財保存修理所 修理報告書 20 | N13: 京都国立博物館 | O13: 京都国立博物館 | P13: 2023
A14: 日本の美術12 | G14: 日本の美術112 | M14: 平成25-27年度 九州国立博物館 文化財修理報告 | N14: 九州国立博物館 | O14: 九州国立博物館 | P14: 2023
A15: 日本の美術13 | G15: 日本の美術113 | M15: 浄土真宗を中心とした祖師信仰とその造形 | N15: 佐々木丞平 | O15: 仏教美術研究上野記念財団 | P15: 2023
A16: 日本の美術14 | G16: 日本の美術114 | M16: タイ所在日本製漆工品に関する調査研究(2) | N16: 二神葉子 | O16: 東京文化財研究所 | P16: 2024
A17: 日本の美術15 | G17: 日本の美術115 | M17: 妙法寺蔵 与謝蕪村筆 寒山拾得図 共同研究報告書 | N17: 東京文化財研究所 | O17: 東京文化財研究所 | P17: 2023 | Q17: 2冊あり
A18: 日本の美術16 | G18: 日本の美術116 | M18: 東京国立博物館所蔵 平安仏画 ―光学調査報告書― | N18: 東京国立博物館・東京文化財研究所 | O18: 東京国立博物館・東京文化財研究所 | P18: 2021
A19: 日本の美術17 | G19: 日本の美術117 | M19: 特別展 平泉 みちのくの浄土 | O19: 大塚巧芸新社 | P19: 2008
A20: 日本の美術18 | G20: 日本の美術118 | M20: ものの記憶 ―色を記録し・伝え・遺す― | N20: 東京文化財研究所 | O20: 東京文化財研究所 | P20: 2024
A21: 日本の美術19 | G21: 日本の美術119 | M21: 和宗総本山 四天王寺所蔵 国宝 扇面法華経冊子 光学調査報告書 カラー写真編 | N21: 東京文化財研究所 | O21: 東京文化財研究所 | P21: 2022
A22: 日本の美術20 | G22: 日本の美術120 | M22: 和宗総本山 四天王寺所蔵 国宝 扇面法華経冊子 光学調査報告書 近紫外線写真・蛍光写真・近赤外線写真編 | N22: 東京文化財研究所 | O22: 東京文化財研究所 | P22: 2023
A23: 日本の美術21 | G23: 日本の美術121 | M23: 和宗総本山 四天王寺所蔵 国宝 扇面法華経冊子 光学調査報告書 蛍光X線分析編 | N23: 東京文化財研究所 | O23: 東京文化財研究所 | P23: 2022
A24: 日本の美術22 | G24: 日本の美術122 | M24: 国宝 法華経（久能寺経） 光学調査報告書 | N24: 東京文化財研究所 | O24: 東京文化財研究所 | P24: 2022
A25: 日本の美術23 | M25: 宮内庁三の丸尚蔵館所蔵 春日権現験記絵 巻十九・巻二十 光学調査報告書 | N25: 東京文化財研究所 | O25: 東京文化財研究所 | P25: 2018
A26: 日本の美術24 | M26: 宮内庁三の丸尚蔵館所蔵 春日権現験記絵 巻十五・巻十六 光学調査報告書 | N26: 東京文化財研究所 | O26: 東京文化財研究所 | P26: 2024
A27: 日本の美術25 | M27: 宮内庁三の丸尚蔵館所蔵 春日権現験記絵 巻十三・巻十四 光学調査報告書 | N27: 東京文化財研究所 | O27: 東京文化財研究所 | P27: 2022
A28: 日本の美術26 | M28: 宮内庁三の丸尚蔵館所蔵 春日権現験記絵 巻十一・巻十二 光学調査報告書 | N28: 東京文化財研究所 | O28: 東京文化財研究所 | P28: 2022
A29: 日本の美術27 | M29: 宮内庁三の丸尚蔵館所蔵 春日権現験記絵 巻九・巻十 光学調査報告書 | N29: 東京文化財研究所 | O29: 東京文化財研究所 | P29: 2021
A30: 日本の美術28 | M30: 宮内庁三の丸尚蔵館所蔵 春日権現験記絵 巻七・巻八 光学調査報告書 | N30: 東京文化財研究所 | O30: 東京文化財研究所 | P30: 2020
A31: 日本の美術29 | M31: 宮内庁三の丸尚蔵館所蔵 春日権現験記絵 巻五・巻六 光学調査報告書 | N31: 東京文化財研究所 | O31: 東京文化財研究所 | P31: 2018
A32: 日本の美術30 | M32: 宮内庁三の丸尚蔵館所蔵 春日権現験記絵 巻三・巻四 光学調査報告書 | N32: 東京文化財研究所 | O32: 東京文化財研究所 | P32: 2017
A33: 日本の美術31 | M33: 宮内庁三の丸尚蔵館所蔵 春日権現験記絵 巻一・巻二 光学調査報告書 | N33: 東京文化財研究所 | O33: 東京文化財研究所 | P33: 2017
A34: 日本の美術32
A35: 日本の美術33
A36: 日本の美術34 | M36: 7段目
A37: 日本の美術35 | M37: 久安六年本 三國祖師影の研究 | N37: 高橋正隆 | P37: 1969
A38: 日本の美術36 | M38: 奈良の寺1 法隆寺 西院伽藍 | N38: 浅野清 | O38: 岩波書店 | P38: 1974
A39: 日本の美術37 | M39: 奈良の寺2 法隆寺 東院伽藍と西院諸堂 | N39: 鈴木嘉吉 | O39: 岩波書店 | P39: 1974
A40: 日本の美術38 | M40: 奈良の寺4 法隆寺 五重塔の塑像 | N40: 長廣敏雄 | O40: 岩波書店 | P40: 1974
...

Sheet 1-C
A1: 書籍・図録名 | B1: 著者名 | C1: 出版社・開催館 | D1: 年 | E1: 備考
A2: 1段目
A3: 魅惑の仏像1 阿修羅 奈良・興福寺 | C3: 毎日新聞社 | D3: 1986
A4: 魅惑の仏像2 千手観音 奈良・唐招提寺金堂 | C4: 毎日新聞社 | D4: 1986
A5: 魅惑の仏像3 釈迦三尊 奈良・法隆寺金堂 | C5: 毎日新聞社 | D5: 1986
A6: 魅惑の仏像4 弥勒菩薩 京都・広隆寺 | C6: 毎日新聞社 | D6: 1986
A7: 魅惑の仏像5 薬師三尊 奈良・薬師寺金堂 | C7: 毎日新聞社 | D7: 1986
A8: 魅惑の仏像6 四天王 奈良・東大寺戒壇堂 | C8: 毎日新聞社 | D8: 1986
A9: 魅惑の仏像7 十一面観音 滋賀・向源寺 | C9: 毎日新聞社 | D9: 1986
A10: 魅惑の仏像8 阿弥陀如来 京都・平等院鳳凰堂 | C10: 毎日新聞社 | D10: 1987
A11: 魅惑の仏像9 十二神将 奈良・新薬師寺 | C11: 毎日新聞社 | D11: 1987
A12: 魅惑の仏像10 盧舎那仏 奈良・唐招提寺金堂 | C12: 毎日新聞社 | D12: 1987
A13: 魅惑の仏像11 五大明王 京都・教王護国寺講堂 | C13: 毎日新聞社 | D13: 1987
A14: 魅惑の仏像12 不空羂索観音 奈良・東大寺法華堂 | C14: 毎日新聞社 | D14: 1987
... A30: 魅惑の仏像28 大日如来 奈良・円成寺多宝塔 | C30: 毎日新聞社 | D30: 1996
A31: 仏像大系1 図でみる仏像篇1 | B31: 国書刊行会 | C31: 国書刊行会 | D31: 1983
A32: 仏像大系2 図でみる仏像篇2 | B32: 国書刊行会 | C32: 国書刊行会 | D32: 1983
A33: 仏像大系3 図でみる仏像篇3 | B33: 国書刊行会 | C33: 国書刊行会 | D33: 1983
A34: 仏像大系4 図でみる仏像篇4 | B34: 国書刊行会 | C34: 国書刊行会 | D34: 1983
A35: 仏像大系5 写真でみる仏像篇1 | B35: 国書刊行会 | C35: 国書刊行会 | D35: 1983
A36: 仏像大系6 写真でみる仏像篇2 | B36: 国書刊行会 | C36: 国書刊行会 | D36: 1983
A37: 仏像大系7 写真でみる仏像篇3 | B37: 国書刊行会 | C37: 国書刊行会 | D37: 1983
A38: 仏像大系8 写真でみる仏像篇4 | B38: 国書刊行会 | C38: 国書刊行会 | D38: 1983
A39: 仏像大系9 写真でみる仏像篇5 | B39: 国書刊行会 | C39: 国書刊行会 | D39: 1983
A40: 仏像大系10 図印篇 | B40: 国書刊行会 | C40: 国書刊行会 | D40: 1983
A41: 仏像大系11 索引・用語解説 | B41: 国書刊行会 | C41: 国書刊行会 | D41: 1983
A42: 日面佛月面佛 中尊寺を中心とする奥州藤原文化圏の宗教彫像に関する調査研究 | B42: 有賀祥隆ほか | D42: 2000-2002
A43: 東國乃仏像 奥州佛教文化圏に遺る宗教彫像の基礎的調査研究 | B43: 有賀祥隆ほか | D43: 2006-2008
A44: 東國乃仏像2 東日本に分布する宗教彫像の基礎的調査研究-古代から中世への変容を軸に | B44: 有賀祥隆ほか | D44: 2006-2008
A45: 東國乃仏像3【報告編】 生身と霊験-宗教的意味を踏まえた仏像の基礎的調査研究 | B45: 有賀祥隆ほか | D45: 2006-2008
A46: 東國乃仏像3【図録編】 生身と霊験-宗教的意味を踏まえた仏像の基礎的調査研究 | B46: 有賀祥隆ほか | D46: 2006-2008
A47: 東國乃仏像4 仏像の表象機能に関わる総合的調査研究-空間・荘厳・胎内に着目して | B47: 有賀祥隆ほか | D47: 2006-2008
A48: 中尊寺を中心とする奥州藤原文化圏の宗教彫像に関する調査研究 | B48: 有賀祥隆ほか | D48: 2000-2002 | E48: 被りあり
A49: 随唐時代の仏舎利信仰と荘厳に関する総合的調査研究 | B49: 加島勝ほか | D49: 2009-2011
A50: 弥勒造像史における「間-世界性」表現の系譜 | B50: 泉武夫ほか | D50: 2017-2021
A51: 「奉為の造像」研究 | B51: 長岡龍作ほか | D51: 2006-2009
A52: 中尊寺を中心とする奥州藤原文化圏美術工芸品に関する総合的調査研究 | B52: 有賀祥隆ほか | D52: 1996-1998
A53: 兜率天往生の思想とそのかたち | B53: 泉武夫ほか | D53: 2007-2010
A55: 2段目
A56: 日本美術全集 別巻 総索引 | B56: 講談社 | C56: 講談社 | D56: 1994
...

Sheet 1-D
